Workbook

Sheet survey
A1: type | B1: name | C1: label | D1: required | E1: calculation | F1: relevant | G1: choice_filter
A2: note | B2: welcome_banner | C2: 🩸 ការធ្វើតេស្តចំណេះដឹង Pre/Post — ការប្រើប្រាស់ RDT "FIRST RESPONSE" កម្មវិធីជាតិកម្ចាត់ជំងឺគ្រុនចាញ់ (CNM) 📝 សំណួរចំនួន ១៥ ស្តីពីការប្រើប្រាស់ និងគុណភាព RDT។ ជោគជ័យ!
A3: select_one test_type | B3: test_type | C3: ប្រភេទតេស្ត | D3: yes
A4: date | B4: test_date | C4: ថ្ងៃខែឆ្នាំ | D4: yes
A5: select_one position | B5: position | C5: តួនាទី | D5: yes
A6: text | B6: position_other | C6: ផ្សេងទៀត — សូមបញ្ជាក់ | D6: yes | F6: ${position}='other'
A7: text | B7: org_name | C7: ឈ្មោះអង្គការ / Name of organization | D7: yes | F7: ${position}='ngo'
A8: select_one province | B8: province | C8: ខេត្ត | D8: yes | F8: ${position}!='ngo'
A9: text | B9: province_other | C9: ផ្សេងទៀត — សូមបញ្ជាក់ | D9: yes | F9: ${province}='other'
A10: select_one od | B10: od | C10: ការិយាល័យប្រតិបត្តិការ (OD) | D10: yes | F10: ${province}!='' and ${position}!='pms' | G10: province_id=${province} or name='other'
A11: text | B11: od_other | C11: ផ្សេងទៀត — សូមបញ្ជាក់ | D11: yes | F11: ${od}='other'
A12: select_one hc | B12: hc | C12: មណ្ឌលសុខភាព (HC) | D12: yes | F12: (${position}='hc' or ${position}='other') and ${od}!='' | G12: od_id=${od} or name='other'
A13: text | B13: hc_other | C13: ផ្សេងទៀត — សូមបញ្ជាក់ | D13: yes | F13: ${hc}='other'
A14: note | B14: instructions | C14: ✅ សូមជ្រើសរើសចម្លើយត្រឹមត្រូវតែមួយសម្រាប់សំណួរនីមួយៗ
A15: select_one q1 | B15: q1 | C15: ១. តើ Malaria RDT ត្រូវបានប្រើសម្រាប់គោលបំណងអ្វី? | D15: yes
A16: select_one q2 | B16: q2 | C16: ២. RDT First Response pLDH/HRP2 Combo អាចរកឃើញ marker សំខាន់ៗអ្វីខ្លះ? | D16: yes
A17: select_one q3 | B17: q3 | C17: ៣. HRP2 មានទំនាក់ទំនងជាចម្បងជាមួយមេរោគប្រភេទណា? | D17: yes
A18: select_one q4 | B18: q4 | C18: ៤. pLDH/PAN ក្នុង RDT មានសារៈសំខាន់អ្វី? | D18: yes
A19: select_one q5 | B19: q5 | C19: ៥. តើសំណាកអ្វីអាចប្រើសម្រាប់ RDT នេះ? | D19: yes
A20: select_one q6 | B20: q6 | C20: ៦. ប្រសិនបើ RDT អវិជ្ជមាន ប៉ុន្តែអ្នកជំងឺមានរោគសញ្ញា និងប្រវត្តិធ្វើដំណើរទៅតំបន់មានហានិភ័យខ្ពស់ តើគួរធ្វើដូចម្ដេច? | D20: yes
A21: select_one q7 | B21: q7 | C21: ៧. ហេតុអ្វីបានជាត្រូវប្រុងប្រយ័ត្នចំពោះ RDT អវិជ្ជមានក្នុងករណី parasite density ទាប? | D21: yes
A22: select_one q8 | B22: q8 | C22: ៨. តើលក្ខខណ្ឌសំខាន់បំផុតមួយក្នុងការរក្សាទុក RDT ដែលបង្ហាញលើប្រអប់នេះគឺអ្វី? | D22: yes
A23: select_one q9 | B23: q9 | C23: ៩. ប្រសិនបើ RDT បង្ហាញលទ្ធផល Positive តើបុគ្គលិកសុខាភិបាលគួរធ្វើអ្វីជំហានបន្ទាប់? | D23: yes
A24: select_one q10 | B24: q10 | C24: ១០. សម្រាប់អ្នកជំងឺដែលត្រូវបានបញ្ជាក់ថាមាន P. vivax តើការគ្រប់គ្រងតាមកម្មវិធីគ្រុនចាញ់កម្ពុជាគួរយកចិត្តទុកដាក់លើអ្វីបន្ថែម? | D24: yes
A25: select_one q11 | B25: q11 | C25: ១១. នៅពេលចុះត្រួតពិនិត្យ RDT នៅមូលដ្ឋានសុខាភិបាល តើចំណុចណាមួយដែលអ្នកត្រួតពិនិត្យត្រូវពិនិត្យជាមុន? | D25: yes
A26: select_one q12 | B26: q12 | C26: ១២. តើហេតុអ្វីបានជាត្រូវពិនិត្យ Lot Number និង Expiry Date របស់ RDT នៅពេល Field Supervision? | D26: yes
... A29: select_one q15 | B29: q15 | C29: ១៥. ប្រសិនបើ Field Supervisor រកឃើញភាពខុសប្រក្រតី ឬលទ្ធផល RDT មិនស្របគ្នា តើសកម្មភាព QA សមស្របបំផុតគឺអ្វី? | D29: yes
A30: calculate | B30: q1_pts | E30: if(${q1}='b',1,0)
A31: calculate | B31: q2_pts | E31: if(${q2}='a',1,0)
A32: calculate | B32: q3_pts | E32: if(${q3}='c',1,0)
A33: calculate | B33: q4_pts | E33: if(${q4}='b',1,0)
A34: calculate | B34: q5_pts | E34: if(${q5}='c',1,0)
A35: calculate | B35: q6_pts | E35: if(${q6}='c',1,0)
A36: calculate | B36: q7_pts | E36: if(${q7}='b',1,0)
A37: calculate | B37: q8_pts | E37: if(${q8}='b',1,0)
A38: calculate | B38: q9_pts | E38: if(${q9}='b',1,0)
A39: calculate | B39: q10_pts | E39: if(${q10}='a',1,0)
A40: calculate | B40: q11_pts | E40: if(${q11}='b',1,0)
A41: calculate | B41: q12_pts | E41: if(${q12}='b',1,0)
... A49: calculate | B49: result_label | E49: if(${total_100} >= 80, 'ជាប់', 'ត្រូវពិនិត្យបន្ថែម')

Sheet choices
A1: list_name | B1: name | C1: label | D1: province_id | E1: od_id
A2: test_type | B2: pre | C2: តេស្តមុនការបណ្ដុះបណ្ដាល
A3: test_type | B3: pos | C3: តេស្តក្រោយការបណ្ដុះបណ្ដាល
A4: position | B4: pms | C4: PMS (Provincial Malaria Supervisor)
A5: position | B5: odms | C5: ODMS (Operational District Malaria Supervisor)
A6: position | B6: hc | C6: HC (Health Center Staff)
A7: position | B7: ngo | C7: NGO / Partner
A8: position | B8: other | C8: ផ្សេងទៀត
A9: province | B9: prov_1 | C9: ស្ទឹងត្រែង
A10: province | B10: prov_2 | C10: ព្រះវិហារ
A11: province | B11: prov_3 | C11: សៀមរាប
A12: province | B12: prov_4 | C12: ឧត្តរមានជ័យ
A13: province | B13: prov_5 | C13: បន្ទាយមានជ័យ
... A15: province | B15: other | C15: ផ្សេងទៀត
A16: od | B16: od_1 | C16: ស្ទឹងត្រែង | D16: prov_1
A17: od | B17: od_2 | C17: ត្បែងមានជ័យ | D17: prov_2
A18: od | B18: od_3 | C18: អង្គរជុំ | D18: prov_3
A19: od | B19: od_4 | C19: ក្រឡាញ់ | D19: prov_3
A20: od | B20: od_5 | C20: សៀមរាប | D20: prov_3
A21: od | B21: od_6 | C21: សូទ្រនិគម | D21: prov_3
A22: od | B22: od_7 | C22: អន្លង់វែង | D22: prov_4
A23: od | B23: od_8 | C23: សំរោង | D23: prov_4
A24: od | B24: od_9 | C24: ម៉ាឡៃ | D24: prov_5
A25: od | B25: od_10 | C25: ប៉ោយប៉ែត | D25: prov_5
A26: od | B26: od_11 | C26: ព្រះនេត្រព្រះ | D26: prov_5
A27: od | B27: od_12 | C27: ថ្មពួក | D27: prov_5
... A31: od | B31: od_16 | C31: ភ្នំស្រួច | D31: prov_6
A32: od | B32: other | C32: ផ្សេងទៀត
A33: hc | B33: hc_1 | C33: Chamkar Leu | E33: od_1
A34: hc | B34: hc_2 | C34: Kamphun | E34: od_1
A35: hc | B35: hc_3 | C35: Kbal Romeas | E35: od_1
A36: hc | B36: hc_4 | C36: Koh Sralay | E36: od_1
A37: hc | B37: hc_5 | C37: Ou Svay | E37: od_1
A38: hc | B38: hc_6 | C38: Preah Rumkel | E38: od_1
A39: hc | B39: hc_7 | C39: Prek Meas | E39: od_1
A40: hc | B40: hc_8 | C40: Samaki | E40: od_1
A41: hc | B41: hc_9 | C41: Santepheap | E41: od_1
A42: hc | B42: hc_10 | C42: Siem Bouk | E42: od_1
A43: hc | B43: hc_11 | C43: Siem Pang | E43: od_1
A44: hc | B44: hc_12 | C44: Sre Krasaing | E44: od_1
...

Sheet settings
A1: form_title | B1: form_id | C1: default_language | D1: style
A2: ការធ្វើតេស្តចំណេះដឹង RDT Pre-Post (CNM) | B2: cnm_rdt_pre_post_test | C2: Khmer (km) | D2: pages

Sheet Coverage
A1: RDT Pre/Post Test — Participant Coverage vs. Form Choice Lists
A2: Expected counts from planning table; HC counts computed from the 'choices' sheet
A4: OD-level detail | F4: Province summary — expected vs. form
A5: Province | B5: OD ID | C5: OD (Khmer) | D5: HC in form | F5: Province | G5: PMS | H5: ODMS | I5: HC (expected) | J5: HC (in form) | K5: Gap | L5: Expected total
A6: Stung Treng | B6: od_1 | C6: =IFERROR(INDEX(choices!$C$2:$C$201,MATCH($B6,choices!$B$2:$B$201,0)),"") | D6: =COUNTIFS(choices!$A$2:$A$201,"hc",choices!$E$2:$E$201,$B6) | F6: Stung Treng | G6: 1 | H6: 1 | I6: 18 | J6: =SUMIFS($D$6:$D$21,$A$6:$A$21,$F6) | K6: =J6-I6 | L6: =G6+H6+I6
A7: Preah Vihear | B7: od_2 | C7: =IFERROR(INDEX(choices!$C$2:$C$201,MATCH($B7,choices!$B$2:$B$201,0)),"") | D7: =COUNTIFS(choices!$A$2:$A$201,"hc",choices!$E$2:$E$201,$B7) | F7: Preah Vihear | G7: 1 | H7: 1 | I7: 18 | J7: =SUMIFS($D$6:$D$21,$A$6:$A$21,$F7) | K7: =J7-I7 | L7: =G7+H7+I7
A8: Siem Reap | B8: od_3 | C8: =IFERROR(INDEX(choices!$C$2:$C$201,MATCH($B8,choices!$B$2:$B$201,0)),"") | D8: =COUNTIFS(choices!$A$2:$A$201,"hc",choices!$E$2:$E$201,$B8) | F8: Siem Reap | G8: 1 | H8: 4 | I8: 34 | J8: =SUMIFS($D$6:$D$21,$A$6:$A$21,$F8) | K8: =J8-I8 | L8: =G8+H8+I8
A9: Siem Reap | B9: od_4 | C9: =IFERROR(INDEX(choices!$C$2:$C$201,MATCH($B9,choices!$B$2:$B$201,0)),"") | D9: =COUNTIFS(choices!$A$2:$A$201,"hc",choices!$E$2:$E$201,$B9) | F9: Oddar Meanchey | G9: 1 | H9: 2 | I9: 10 | J9: =SUMIFS($D$6:$D$21,$A$6:$A$21,$F9) | K9: =J9-I9 | L9: =G9+H9+I9
A10: Siem Reap | B10: od_5 | C10: =IFERROR(INDEX(choices!$C$2:$C$201,MATCH($B10,choices!$B$2:$B$201,0)),"") | D10: =COUNTIFS(choices!$A$2:$A$201,"hc",choices!$E$2:$E$201,$B10) | F10: Banteay Meanchey | G10: 1 | H10: 4 | I10: 12 | J10: =SUMIFS($D$6:$D$21,$A$6:$A$21,$F10) | K10: =J10-I10 | L10: =G10+H10+I10
A11: Siem Reap | B11: od_6 | C11: =IFERROR(INDEX(choices!$C$2:$C$201,MATCH($B11,choices!$B$2:$B$201,0)),"") | D11: =COUNTIFS(choices!$A$2:$A$201,"hc",choices!$E$2:$E$201,$B11) | F11: Kampong Speu | G11: 1 | H11: 4 | I11: 19 | J11: =SUMIFS($D$6:$D$21,$A$6:$A$21,$F11) | K11: =J11-I11 | L11: =G11+H11+I11
A12: Oddar Meanchey | B12: od_7 | C12: =IFERROR(INDEX(choices!$C$2:$C$201,MATCH($B12,choices!$B$2:$B$201,0)),"") | D12: =COUNTIFS(choices!$A$2:$A$201,"hc",choices!$E$2:$E$201,$B12) | F12: Total | G12: =SUM(G6:G11) | H12: =SUM(H6:H11) | I12: =SUM(I6:I11) | J12: =SUM(J6:J11) | K12: =SUM(K6:K11) | L12: =SUM(L6:L11)
A13: Oddar Meanchey | B13: od_8 | C13: =IFERROR(INDEX(choices!$C$2:$C$201,MATCH($B13,choices!$B$2:$B$201,0)),"") | D13: =COUNTIFS(choices!$A$2:$A$201,"hc",choices!$E$2:$E$201,$B13)
A14: Banteay Meanchey | B14: od_9 | C14: =IFERROR(INDEX(choices!$C$2:$C$201,MATCH($B14,choices!$B$2:$B$201,0)),"") | D14: =COUNTIFS(choices!$A$2:$A$201,"hc",choices!$E$2:$E$201,$B14) | F14: Discrepancies to resolve
A15: Banteay Meanchey | B15: od_10 | C15: =IFERROR(INDEX(choices!$C$2:$C$201,MATCH($B15,choices!$B$2:$B$201,0)),"") | D15: =COUNTIFS(choices!$A$2:$A$201,"hc",choices!$E$2:$E$201,$B15) | F15: Siem Reap: form has 32 HC vs 34 expected (2 short) — Angkor Chum OD has only 3 HC
A16: Banteay Meanchey | B16: od_11 | C16: =IFERROR(INDEX(choices!$C$2:$C$201,MATCH($B16,choices!$B$2:$B$201,0)),"") | D16: =COUNTIFS(choices!$A$2:$A$201,"hc",choices!$E$2:$E$201,$B16) | F16: Oddar Meanchey: 9 vs 10 (1 short) — Samraong OD has only 3 HC
A17: Banteay Meanchey | B17: od_12 | C17: =IFERROR(INDEX(choices!$C$2:$C$201,MATCH($B17,choices!$B$2:$B$201,0)),"") | D17: =COUNTIFS(choices!$A$2:$A$201,"hc",choices!$E$2:$E$201,$B17) | F17: Banteay Meanchey: 11 vs 12 (1 short) — Preah Netr Preah OD has only 1 HC (Nam Tau)
A18: Kampong Speu | B18: od_13 | C18: =IFERROR(INDEX(choices!$C$2:$C$201,MATCH($B18,choices!$B$2:$B$201,0)),"") | D18: =COUNTIFS(choices!$A$2:$A$201,"hc",choices!$E$2:$E$201,$B18) | F18: Kampong Speu: 21 vs 19 (2 extra) — verify which HC belong in scope
A19: Kampong Speu | B19: od_14 | C19: =IFERROR(INDEX(choices!$C$2:$C$201,MATCH($B19,choices!$B$2:$B$201,0)),"") | D19: =COUNTIFS(choices!$A$2:$A$201,"hc",choices!$E$2:$E$201,$B19) | F19: Net effect: 109 HC in form vs 111 expected
A20: Kampong Speu | B20: od_15 | C20: =IFERROR(INDEX(choices!$C$2:$C$201,MATCH($B20,choices!$B$2:$B$201,0)),"") | D20: =COUNTIFS(choices!$A$2:$A$201,"hc",choices!$E$2:$E$201,$B20)
A21: Kampong Speu | B21: od_16 | C21: =IFERROR(INDEX(choices!$C$2:$C$201,MATCH($B21,choices!$B$2:$B$201,0)),"") | D21: =COUNTIFS(choices!$A$2:$A$201,"hc",choices!$E$2:$E$201,$B21)
